[2024-08-26T04:27:47.291+0000] {local_task_job_runner.py:123} INFO - ::group::Pre task execution logs
[2024-08-26T04:27:47.320+0000] {taskinstance.py:2603} INFO - Dependencies all met for dep_context=non-requeueable deps ti=<TaskInstance: data_generation_dag.run_data_generation_script manual__2024-08-26T04:27:46.327027+00:00 [queued]>
[2024-08-26T04:27:47.331+0000] {taskinstance.py:2603} INFO - Dependencies all met for dep_context=requeueable deps ti=<TaskInstance: data_generation_dag.run_data_generation_script manual__2024-08-26T04:27:46.327027+00:00 [queued]>
[2024-08-26T04:27:47.332+0000] {taskinstance.py:2856} INFO - Starting attempt 1 of 2
[2024-08-26T04:27:47.356+0000] {taskinstance.py:2879} INFO - Executing <Task(BashOperator): run_data_generation_script> on 2024-08-26 04:27:46.327027+00:00
[2024-08-26T04:27:47.371+0000] {logging_mixin.py:190} WARNING - /home/***/.local/lib/python3.12/site-packages/***/task/task_runner/standard_task_runner.py:70 DeprecationWarning: This process (pid=225) is multi-threaded, use of fork() may lead to deadlocks in the child.
[2024-08-26T04:27:47.370+0000] {standard_task_runner.py:104} INFO - Running: ['***', 'tasks', 'run', 'data_generation_dag', 'run_data_generation_script', 'manual__2024-08-26T04:27:46.327027+00:00', '--job-id', '162', '--raw', '--subdir', 'DAGS_FOLDER/postgres_dags.py', '--cfg-path', '/tmp/tmprv8oq9e6']
[2024-08-26T04:27:47.372+0000] {standard_task_runner.py:72} INFO - Started process 226 to run task
[2024-08-26T04:27:47.373+0000] {standard_task_runner.py:105} INFO - Job 162: Subtask run_data_generation_script
[2024-08-26T04:27:47.453+0000] {task_command.py:467} INFO - Running <TaskInstance: data_generation_dag.run_data_generation_script manual__2024-08-26T04:27:46.327027+00:00 [running]> on host f00445136288
[2024-08-26T04:27:47.595+0000] {taskinstance.py:3122} INFO - Exporting env vars: AIRFLOW_CTX_DAG_OWNER='***' AIRFLOW_CTX_DAG_ID='data_generation_dag' AIRFLOW_CTX_TASK_ID='run_data_generation_script' AIRFLOW_CTX_EXECUTION_DATE='2024-08-26T04:27:46.327027+00:00' AIRFLOW_CTX_TRY_NUMBER='1' AIRFLOW_CTX_DAG_RUN_ID='manual__2024-08-26T04:27:46.327027+00:00'
[2024-08-26T04:27:47.597+0000] {taskinstance.py:731} INFO - ::endgroup::
[2024-08-26T04:27:47.639+0000] {subprocess.py:63} INFO - Tmp dir root location: /tmp
[2024-08-26T04:27:47.640+0000] {subprocess.py:75} INFO - Running command: ['/usr/bin/bash', '-c', 'python3 /opt/***/fake/Fake.py']
[2024-08-26T04:27:47.661+0000] {subprocess.py:86} INFO - Output:
[2024-08-26T04:27:47.869+0000] {subprocess.py:93} INFO - Traceback (most recent call last):
[2024-08-26T04:27:47.870+0000] {subprocess.py:93} INFO -   File "/opt/***/fake/Fake.py", line 2, in <module>
[2024-08-26T04:27:47.871+0000] {subprocess.py:93} INFO -     from faker import Faker
[2024-08-26T04:27:47.873+0000] {subprocess.py:93} INFO - ModuleNotFoundError: No module named 'faker'
[2024-08-26T04:27:47.884+0000] {subprocess.py:97} INFO - Command exited with return code 1
[2024-08-26T04:27:47.908+0000] {taskinstance.py:3301} ERROR - Task failed with exception
Traceback (most recent call last):
  File "/home/airflow/.local/lib/python3.12/site-packages/airflow/models/taskinstance.py", line 767, in _execute_task
    result = _execute_callable(context=context, **execute_callable_kwargs)
             ^^^^^^^^^^^^^^^^^^^^^^^^^^^^^^^^^^^^^^^^^^^^^^^^^^^^^^^^^^^^^
  File "/home/airflow/.local/lib/python3.12/site-packages/airflow/models/taskinstance.py", line 733, in _execute_callable
    return ExecutionCallableRunner(
           ^^^^^^^^^^^^^^^^^^^^^^^^
  File "/home/airflow/.local/lib/python3.12/site-packages/airflow/utils/operator_helpers.py", line 252, in run
    return self.func(*args, **kwargs)
           ^^^^^^^^^^^^^^^^^^^^^^^^^^
  File "/home/airflow/.local/lib/python3.12/site-packages/airflow/models/baseoperator.py", line 406, in wrapper
    return func(self, *args, **kwargs)
           ^^^^^^^^^^^^^^^^^^^^^^^^^^^
  File "/home/airflow/.local/lib/python3.12/site-packages/airflow/operators/bash.py", line 249, in execute
    raise AirflowException(
airflow.exceptions.AirflowException: Bash command failed. The command returned a non-zero exit code 1.
[2024-08-26T04:27:47.930+0000] {taskinstance.py:1225} INFO - Marking task as UP_FOR_RETRY. dag_id=data_generation_dag, task_id=run_data_generation_script, run_id=manual__2024-08-26T04:27:46.327027+00:00, execution_date=20240826T042746, start_date=20240826T042747, end_date=20240826T042747
[2024-08-26T04:27:47.955+0000] {taskinstance.py:340} INFO - ::group::Post task execution logs
[2024-08-26T04:27:47.956+0000] {standard_task_runner.py:124} ERROR - Failed to execute job 162 for task run_data_generation_script (Bash command failed. The command returned a non-zero exit code 1.; 226)
Traceback (most recent call last):
  File "/home/airflow/.local/lib/python3.12/site-packages/airflow/task/task_runner/standard_task_runner.py", line 117, in _start_by_fork
    ret = args.func(args, dag=self.dag)
          ^^^^^^^^^^^^^^^^^^^^^^^^^^^^^
  File "/home/airflow/.local/lib/python3.12/site-packages/airflow/cli/cli_config.py", line 49, in command
    return func(*args, **kwargs)
           ^^^^^^^^^^^^^^^^^^^^^
  File "/home/airflow/.local/lib/python3.12/site-packages/airflow/utils/cli.py", line 115, in wrapper
    return f(*args, **kwargs)
           ^^^^^^^^^^^^^^^^^^
  File "/home/airflow/.local/lib/python3.12/site-packages/airflow/cli/commands/task_command.py", line 483, in task_run
    task_return_code = _run_task_by_selected_method(args, _dag, ti)
                       ^^^^^^^^^^^^^^^^^^^^^^^^^^^^^^^^^^^^^^^^^^^^
  File "/home/airflow/.local/lib/python3.12/site-packages/airflow/cli/commands/task_command.py", line 256, in _run_task_by_selected_method
    return _run_raw_task(args, ti)
           ^^^^^^^^^^^^^^^^^^^^^^^
  File "/home/airflow/.local/lib/python3.12/site-packages/airflow/cli/commands/task_command.py", line 341, in _run_raw_task
    return ti._run_raw_task(
           ^^^^^^^^^^^^^^^^^
  File "/home/airflow/.local/lib/python3.12/site-packages/airflow/utils/session.py", line 97, in wrapper
    return func(*args, session=session, **kwargs)
           ^^^^^^^^^^^^^^^^^^^^^^^^^^^^^^^^^^^^^^
  File "/home/airflow/.local/lib/python3.12/site-packages/airflow/models/taskinstance.py", line 2995, in _run_raw_task
    return _run_raw_task(
           ^^^^^^^^^^^^^^
  File "/home/airflow/.local/lib/python3.12/site-packages/airflow/models/taskinstance.py", line 273, in _run_raw_task
    TaskInstance._execute_task_with_callbacks(
  File "/home/airflow/.local/lib/python3.12/site-packages/airflow/models/taskinstance.py", line 3149, in _execute_task_with_callbacks
    result = self._execute_task(context, task_orig)
             ^^^^^^^^^^^^^^^^^^^^^^^^^^^^^^^^^^^^^^
  File "/home/airflow/.local/lib/python3.12/site-packages/airflow/models/taskinstance.py", line 3173, in _execute_task
    return _execute_task(self, context, task_orig)
           ^^^^^^^^^^^^^^^^^^^^^^^^^^^^^^^^^^^^^^^
  File "/home/airflow/.local/lib/python3.12/site-packages/airflow/models/taskinstance.py", line 767, in _execute_task
    result = _execute_callable(context=context, **execute_callable_kwargs)
             ^^^^^^^^^^^^^^^^^^^^^^^^^^^^^^^^^^^^^^^^^^^^^^^^^^^^^^^^^^^^^
  File "/home/airflow/.local/lib/python3.12/site-packages/airflow/models/taskinstance.py", line 733, in _execute_callable
    return ExecutionCallableRunner(
           ^^^^^^^^^^^^^^^^^^^^^^^^
  File "/home/airflow/.local/lib/python3.12/site-packages/airflow/utils/operator_helpers.py", line 252, in run
    return self.func(*args, **kwargs)
           ^^^^^^^^^^^^^^^^^^^^^^^^^^
  File "/home/airflow/.local/lib/python3.12/site-packages/airflow/models/baseoperator.py", line 406, in wrapper
    return func(self, *args, **kwargs)
           ^^^^^^^^^^^^^^^^^^^^^^^^^^^
  File "/home/airflow/.local/lib/python3.12/site-packages/airflow/operators/bash.py", line 249, in execute
    raise AirflowException(
airflow.exceptions.AirflowException: Bash command failed. The command returned a non-zero exit code 1.
[2024-08-26T04:27:48.006+0000] {local_task_job_runner.py:261} INFO - Task exited with return code 1
[2024-08-26T04:27:48.031+0000] {taskinstance.py:3891} INFO - 0 downstream tasks scheduled from follow-on schedule check
[2024-08-26T04:27:48.034+0000] {local_task_job_runner.py:240} INFO - ::endgroup::
