[2024-08-25T05:40:20.650+0000] {local_task_job_runner.py:123} INFO - ::group::Pre task execution logs
[2024-08-25T05:40:20.679+0000] {taskinstance.py:2603} INFO - Dependencies all met for dep_context=non-requeueable deps ti=<TaskInstance: extract_data_dag.run_python_script scheduled__2024-08-24T00:00:00+00:00 [queued]>
[2024-08-25T05:40:20.692+0000] {taskinstance.py:2603} INFO - Dependencies all met for dep_context=requeueable deps ti=<TaskInstance: extract_data_dag.run_python_script scheduled__2024-08-24T00:00:00+00:00 [queued]>
[2024-08-25T05:40:20.693+0000] {taskinstance.py:2856} INFO - Starting attempt 1 of 2
[2024-08-25T05:40:20.719+0000] {taskinstance.py:2879} INFO - Executing <Task(BashOperator): run_python_script> on 2024-08-24 00:00:00+00:00
[2024-08-25T05:40:20.731+0000] {logging_mixin.py:190} WARNING - /home/***/.local/lib/python3.12/site-packages/***/task/task_runner/standard_task_runner.py:70 DeprecationWarning: This process (pid=659) is multi-threaded, use of fork() may lead to deadlocks in the child.
[2024-08-25T05:40:20.733+0000] {standard_task_runner.py:72} INFO - Started process 660 to run task
[2024-08-25T05:40:20.730+0000] {standard_task_runner.py:104} INFO - Running: ['***', 'tasks', 'run', 'extract_data_dag', 'run_python_script', 'scheduled__2024-08-24T00:00:00+00:00', '--job-id', '36', '--raw', '--subdir', 'DAGS_FOLDER/test.py', '--cfg-path', '/tmp/tmp5_na15ob']
[2024-08-25T05:40:20.734+0000] {standard_task_runner.py:105} INFO - Job 36: Subtask run_python_script
[2024-08-25T05:40:20.804+0000] {task_command.py:467} INFO - Running <TaskInstance: extract_data_dag.run_python_script scheduled__2024-08-24T00:00:00+00:00 [running]> on host 05371bfc828b
[2024-08-25T05:40:20.936+0000] {taskinstance.py:3122} INFO - Exporting env vars: AIRFLOW_CTX_DAG_OWNER='***' AIRFLOW_CTX_DAG_ID='extract_data_dag' AIRFLOW_CTX_TASK_ID='run_python_script' AIRFLOW_CTX_EXECUTION_DATE='2024-08-24T00:00:00+00:00' AIRFLOW_CTX_TRY_NUMBER='1' AIRFLOW_CTX_DAG_RUN_ID='scheduled__2024-08-24T00:00:00+00:00'
[2024-08-25T05:40:20.937+0000] {taskinstance.py:731} INFO - ::endgroup::
[2024-08-25T05:40:20.981+0000] {subprocess.py:63} INFO - Tmp dir root location: /tmp
[2024-08-25T05:40:20.982+0000] {subprocess.py:75} INFO - Running command: ['/usr/bin/bash', '-c', 'python3 /home/lapthanh/Documents/DW_PROJECT/Airflow/spark/app/extract.py']
[2024-08-25T05:40:20.996+0000] {subprocess.py:86} INFO - Output:
[2024-08-25T05:40:21.055+0000] {subprocess.py:93} INFO - python3: can't open file '/home/lapthanh/Documents/DW_PROJECT/Airflow/spark/app/extract.py': [Errno 2] No such file or directory
[2024-08-25T05:40:21.067+0000] {subprocess.py:97} INFO - Command exited with return code 2
[2024-08-25T05:40:21.104+0000] {taskinstance.py:3301} ERROR - Task failed with exception
Traceback (most recent call last):
  File "/home/airflow/.local/lib/python3.12/site-packages/airflow/models/taskinstance.py", line 767, in _execute_task
    result = _execute_callable(context=context, **execute_callable_kwargs)
             ^^^^^^^^^^^^^^^^^^^^^^^^^^^^^^^^^^^^^^^^^^^^^^^^^^^^^^^^^^^^^
  File "/home/airflow/.local/lib/python3.12/site-packages/airflow/models/taskinstance.py", line 733, in _execute_callable
    return ExecutionCallableRunner(
           ^^^^^^^^^^^^^^^^^^^^^^^^
  File "/home/airflow/.local/lib/python3.12/site-packages/airflow/utils/operator_helpers.py", line 252, in run
    return self.func(*args, **kwargs)
           ^^^^^^^^^^^^^^^^^^^^^^^^^^
  File "/home/airflow/.local/lib/python3.12/site-packages/airflow/models/baseoperator.py", line 406, in wrapper
    return func(self, *args, **kwargs)
           ^^^^^^^^^^^^^^^^^^^^^^^^^^^
  File "/home/airflow/.local/lib/python3.12/site-packages/airflow/operators/bash.py", line 249, in execute
    raise AirflowException(
airflow.exceptions.AirflowException: Bash command failed. The command returned a non-zero exit code 2.
[2024-08-25T05:40:21.128+0000] {taskinstance.py:1225} INFO - Marking task as UP_FOR_RETRY. dag_id=extract_data_dag, task_id=run_python_script, run_id=scheduled__2024-08-24T00:00:00+00:00, execution_date=20240824T000000, start_date=20240825T054020, end_date=20240825T054021
[2024-08-25T05:40:21.174+0000] {taskinstance.py:340} INFO - ::group::Post task execution logs
[2024-08-25T05:40:21.176+0000] {standard_task_runner.py:124} ERROR - Failed to execute job 36 for task run_python_script (Bash command failed. The command returned a non-zero exit code 2.; 660)
Traceback (most recent call last):
  File "/home/airflow/.local/lib/python3.12/site-packages/airflow/task/task_runner/standard_task_runner.py", line 117, in _start_by_fork
    ret = args.func(args, dag=self.dag)
          ^^^^^^^^^^^^^^^^^^^^^^^^^^^^^
  File "/home/airflow/.local/lib/python3.12/site-packages/airflow/cli/cli_config.py", line 49, in command
    return func(*args, **kwargs)
           ^^^^^^^^^^^^^^^^^^^^^
  File "/home/airflow/.local/lib/python3.12/site-packages/airflow/utils/cli.py", line 115, in wrapper
    return f(*args, **kwargs)
           ^^^^^^^^^^^^^^^^^^
  File "/home/airflow/.local/lib/python3.12/site-packages/airflow/cli/commands/task_command.py", line 483, in task_run
    task_return_code = _run_task_by_selected_method(args, _dag, ti)
                       ^^^^^^^^^^^^^^^^^^^^^^^^^^^^^^^^^^^^^^^^^^^^
  File "/home/airflow/.local/lib/python3.12/site-packages/airflow/cli/commands/task_command.py", line 256, in _run_task_by_selected_method
    return _run_raw_task(args, ti)
           ^^^^^^^^^^^^^^^^^^^^^^^
  File "/home/airflow/.local/lib/python3.12/site-packages/airflow/cli/commands/task_command.py", line 341, in _run_raw_task
    return ti._run_raw_task(
           ^^^^^^^^^^^^^^^^^
  File "/home/airflow/.local/lib/python3.12/site-packages/airflow/utils/session.py", line 97, in wrapper
    return func(*args, session=session, **kwargs)
           ^^^^^^^^^^^^^^^^^^^^^^^^^^^^^^^^^^^^^^
  File "/home/airflow/.local/lib/python3.12/site-packages/airflow/models/taskinstance.py", line 2995, in _run_raw_task
    return _run_raw_task(
           ^^^^^^^^^^^^^^
  File "/home/airflow/.local/lib/python3.12/site-packages/airflow/models/taskinstance.py", line 273, in _run_raw_task
    TaskInstance._execute_task_with_callbacks(
  File "/home/airflow/.local/lib/python3.12/site-packages/airflow/models/taskinstance.py", line 3149, in _execute_task_with_callbacks
    result = self._execute_task(context, task_orig)
             ^^^^^^^^^^^^^^^^^^^^^^^^^^^^^^^^^^^^^^
  File "/home/airflow/.local/lib/python3.12/site-packages/airflow/models/taskinstance.py", line 3173, in _execute_task
    return _execute_task(self, context, task_orig)
           ^^^^^^^^^^^^^^^^^^^^^^^^^^^^^^^^^^^^^^^
  File "/home/airflow/.local/lib/python3.12/site-packages/airflow/models/taskinstance.py", line 767, in _execute_task
    result = _execute_callable(context=context, **execute_callable_kwargs)
             ^^^^^^^^^^^^^^^^^^^^^^^^^^^^^^^^^^^^^^^^^^^^^^^^^^^^^^^^^^^^^
  File "/home/airflow/.local/lib/python3.12/site-packages/airflow/models/taskinstance.py", line 733, in _execute_callable
    return ExecutionCallableRunner(
           ^^^^^^^^^^^^^^^^^^^^^^^^
  File "/home/airflow/.local/lib/python3.12/site-packages/airflow/utils/operator_helpers.py", line 252, in run
    return self.func(*args, **kwargs)
           ^^^^^^^^^^^^^^^^^^^^^^^^^^
  File "/home/airflow/.local/lib/python3.12/site-packages/airflow/models/baseoperator.py", line 406, in wrapper
    return func(self, *args, **kwargs)
           ^^^^^^^^^^^^^^^^^^^^^^^^^^^
  File "/home/airflow/.local/lib/python3.12/site-packages/airflow/operators/bash.py", line 249, in execute
    raise AirflowException(
airflow.exceptions.AirflowException: Bash command failed. The command returned a non-zero exit code 2.
[2024-08-25T05:40:21.203+0000] {local_task_job_runner.py:261} INFO - Task exited with return code 1
[2024-08-25T05:40:21.254+0000] {taskinstance.py:3891} INFO - 0 downstream tasks scheduled from follow-on schedule check
[2024-08-25T05:40:21.259+0000] {local_task_job_runner.py:240} INFO - ::endgroup::
