[2024-08-25T06:44:12.658+0000] {local_task_job_runner.py:123} INFO - ::group::Pre task execution logs
[2024-08-25T06:44:12.682+0000] {taskinstance.py:2603} INFO - Dependencies all met for dep_context=non-requeueable deps ti=<TaskInstance: extract_data_dag.run_python_script manual__2024-08-25T06:44:11.422250+00:00 [queued]>
[2024-08-25T06:44:12.694+0000] {taskinstance.py:2603} INFO - Dependencies all met for dep_context=requeueable deps ti=<TaskInstance: extract_data_dag.run_python_script manual__2024-08-25T06:44:11.422250+00:00 [queued]>
[2024-08-25T06:44:12.695+0000] {taskinstance.py:2856} INFO - Starting attempt 1 of 2
[2024-08-25T06:44:12.716+0000] {taskinstance.py:2879} INFO - Executing <Task(BashOperator): run_python_script> on 2024-08-25 06:44:11.422250+00:00
[2024-08-25T06:44:12.726+0000] {logging_mixin.py:190} WARNING - /home/***/.local/lib/python3.12/site-packages/***/task/task_runner/standard_task_runner.py:70 DeprecationWarning: This process (pid=421) is multi-threaded, use of fork() may lead to deadlocks in the child.
[2024-08-25T06:44:12.727+0000] {standard_task_runner.py:72} INFO - Started process 424 to run task
[2024-08-25T06:44:12.726+0000] {standard_task_runner.py:104} INFO - Running: ['***', 'tasks', 'run', 'extract_data_dag', 'run_python_script', 'manual__2024-08-25T06:44:11.422250+00:00', '--job-id', '60', '--raw', '--subdir', 'DAGS_FOLDER/test.py', '--cfg-path', '/tmp/tmpbz4__6er']
[2024-08-25T06:44:12.728+0000] {standard_task_runner.py:105} INFO - Job 60: Subtask run_python_script
[2024-08-25T06:44:12.798+0000] {task_command.py:467} INFO - Running <TaskInstance: extract_data_dag.run_python_script manual__2024-08-25T06:44:11.422250+00:00 [running]> on host c252a95a8cff
[2024-08-25T06:44:12.931+0000] {taskinstance.py:3122} INFO - Exporting env vars: AIRFLOW_CTX_DAG_OWNER='***' AIRFLOW_CTX_DAG_ID='extract_data_dag' AIRFLOW_CTX_TASK_ID='run_python_script' AIRFLOW_CTX_EXECUTION_DATE='2024-08-25T06:44:11.422250+00:00' AIRFLOW_CTX_TRY_NUMBER='1' AIRFLOW_CTX_DAG_RUN_ID='manual__2024-08-25T06:44:11.422250+00:00'
[2024-08-25T06:44:12.932+0000] {taskinstance.py:731} INFO - ::endgroup::
[2024-08-25T06:44:12.946+0000] {subprocess.py:63} INFO - Tmp dir root location: /tmp
[2024-08-25T06:44:12.947+0000] {subprocess.py:75} INFO - Running command: ['/usr/bin/bash', '-c', 'python3 /spark/app/extract.py']
[2024-08-25T06:44:12.963+0000] {subprocess.py:86} INFO - Output:
[2024-08-25T06:44:14.212+0000] {subprocess.py:93} INFO - Lỗi khi đọc bảng customers: (psycopg2.OperationalError) connection to server at "127.0.0.1", port 5432 failed: Connection refused
[2024-08-25T06:44:14.213+0000] {subprocess.py:93} INFO - 	Is the server running on that host and accepting TCP/IP connections?
[2024-08-25T06:44:14.213+0000] {subprocess.py:93} INFO - 
[2024-08-25T06:44:14.214+0000] {subprocess.py:93} INFO - (Background on this error at: https://sqlalche.me/e/14/e3q8)
[2024-08-25T06:44:14.215+0000] {subprocess.py:93} INFO - Lỗi khi đọc bảng accounts: (psycopg2.OperationalError) connection to server at "127.0.0.1", port 5432 failed: Connection refused
[2024-08-25T06:44:14.216+0000] {subprocess.py:93} INFO - 	Is the server running on that host and accepting TCP/IP connections?
[2024-08-25T06:44:14.218+0000] {subprocess.py:93} INFO - 
[2024-08-25T06:44:14.218+0000] {subprocess.py:93} INFO - (Background on this error at: https://sqlalche.me/e/14/e3q8)
[2024-08-25T06:44:14.220+0000] {subprocess.py:93} INFO - Lỗi khi đọc bảng transactions: (psycopg2.OperationalError) connection to server at "127.0.0.1", port 5432 failed: Connection refused
[2024-08-25T06:44:14.220+0000] {subprocess.py:93} INFO - 	Is the server running on that host and accepting TCP/IP connections?
[2024-08-25T06:44:14.221+0000] {subprocess.py:93} INFO - 
[2024-08-25T06:44:14.221+0000] {subprocess.py:93} INFO - (Background on this error at: https://sqlalche.me/e/14/e3q8)
[2024-08-25T06:44:14.221+0000] {subprocess.py:93} INFO - Lỗi khi đọc bảng branches: (psycopg2.OperationalError) connection to server at "127.0.0.1", port 5432 failed: Connection refused
[2024-08-25T06:44:14.222+0000] {subprocess.py:93} INFO - 	Is the server running on that host and accepting TCP/IP connections?
[2024-08-25T06:44:14.222+0000] {subprocess.py:93} INFO - 
[2024-08-25T06:44:14.224+0000] {subprocess.py:93} INFO - (Background on this error at: https://sqlalche.me/e/14/e3q8)
[2024-08-25T06:44:14.225+0000] {subprocess.py:93} INFO - Lỗi khi đọc bảng loans: (psycopg2.OperationalError) connection to server at "127.0.0.1", port 5432 failed: Connection refused
[2024-08-25T06:44:14.226+0000] {subprocess.py:93} INFO - 	Is the server running on that host and accepting TCP/IP connections?
[2024-08-25T06:44:14.227+0000] {subprocess.py:93} INFO - 
[2024-08-25T06:44:14.228+0000] {subprocess.py:93} INFO - (Background on this error at: https://sqlalche.me/e/14/e3q8)
[2024-08-25T06:44:14.229+0000] {subprocess.py:93} INFO - Lỗi khi đọc bảng credit_cards: (psycopg2.OperationalError) connection to server at "127.0.0.1", port 5432 failed: Connection refused
[2024-08-25T06:44:14.229+0000] {subprocess.py:93} INFO - 	Is the server running on that host and accepting TCP/IP connections?
[2024-08-25T06:44:14.231+0000] {subprocess.py:93} INFO - 
[2024-08-25T06:44:14.232+0000] {subprocess.py:93} INFO - (Background on this error at: https://sqlalche.me/e/14/e3q8)
[2024-08-25T06:44:14.233+0000] {subprocess.py:93} INFO - Lỗi khi đọc bảng transaction_history: (psycopg2.OperationalError) connection to server at "127.0.0.1", port 5432 failed: Connection refused
[2024-08-25T06:44:14.233+0000] {subprocess.py:93} INFO - 	Is the server running on that host and accepting TCP/IP connections?
[2024-08-25T06:44:14.234+0000] {subprocess.py:93} INFO - 
[2024-08-25T06:44:14.235+0000] {subprocess.py:93} INFO - (Background on this error at: https://sqlalche.me/e/14/e3q8)
[2024-08-25T06:44:14.235+0000] {subprocess.py:93} INFO - Lỗi khi đọc bảng payment: (psycopg2.OperationalError) connection to server at "127.0.0.1", port 5432 failed: Connection refused
[2024-08-25T06:44:14.236+0000] {subprocess.py:93} INFO - 	Is the server running on that host and accepting TCP/IP connections?
[2024-08-25T06:44:14.237+0000] {subprocess.py:93} INFO - 
[2024-08-25T06:44:14.238+0000] {subprocess.py:93} INFO - (Background on this error at: https://sqlalche.me/e/14/e3q8)
[2024-08-25T06:44:14.239+0000] {subprocess.py:93} INFO - Lỗi khi đọc bảng investments: (psycopg2.OperationalError) connection to server at "127.0.0.1", port 5432 failed: Connection refused
[2024-08-25T06:44:14.240+0000] {subprocess.py:93} INFO - 	Is the server running on that host and accepting TCP/IP connections?
[2024-08-25T06:44:14.241+0000] {subprocess.py:93} INFO - 
[2024-08-25T06:44:14.242+0000] {subprocess.py:93} INFO - (Background on this error at: https://sqlalche.me/e/14/e3q8)
[2024-08-25T06:44:14.357+0000] {subprocess.py:97} INFO - Command exited with return code 0
[2024-08-25T06:44:14.396+0000] {taskinstance.py:340} INFO - ::group::Post task execution logs
[2024-08-25T06:44:14.397+0000] {taskinstance.py:352} INFO - Marking task as SUCCESS. dag_id=extract_data_dag, task_id=run_python_script, run_id=manual__2024-08-25T06:44:11.422250+00:00, execution_date=20240825T064411, start_date=20240825T064412, end_date=20240825T064414
[2024-08-25T06:44:14.426+0000] {local_task_job_runner.py:261} INFO - Task exited with return code 0
[2024-08-25T06:44:14.456+0000] {taskinstance.py:3891} INFO - 0 downstream tasks scheduled from follow-on schedule check
[2024-08-25T06:44:14.458+0000] {local_task_job_runner.py:240} INFO - ::endgroup::
