[2024-08-25T05:53:28.006+0000] {local_task_job_runner.py:123} INFO - ::group::Pre task execution logs
[2024-08-25T05:53:28.038+0000] {taskinstance.py:2603} INFO - Dependencies all met for dep_context=non-requeueable deps ti=<TaskInstance: extract_data_dag.run_python_script manual__2024-08-25T05:53:27.514769+00:00 [queued]>
[2024-08-25T05:53:28.059+0000] {taskinstance.py:2603} INFO - Dependencies all met for dep_context=requeueable deps ti=<TaskInstance: extract_data_dag.run_python_script manual__2024-08-25T05:53:27.514769+00:00 [queued]>
[2024-08-25T05:53:28.060+0000] {taskinstance.py:2856} INFO - Starting attempt 1 of 2
[2024-08-25T05:53:28.093+0000] {taskinstance.py:2879} INFO - Executing <Task(BashOperator): run_python_script> on 2024-08-25 05:53:27.514769+00:00
[2024-08-25T05:53:28.108+0000] {logging_mixin.py:190} WARNING - /home/***/.local/lib/python3.12/site-packages/***/task/task_runner/standard_task_runner.py:70 DeprecationWarning: This process (pid=831) is multi-threaded, use of fork() may lead to deadlocks in the child.
[2024-08-25T05:53:28.111+0000] {standard_task_runner.py:72} INFO - Started process 832 to run task
[2024-08-25T05:53:28.110+0000] {standard_task_runner.py:104} INFO - Running: ['***', 'tasks', 'run', 'extract_data_dag', 'run_python_script', 'manual__2024-08-25T05:53:27.514769+00:00', '--job-id', '40', '--raw', '--subdir', 'DAGS_FOLDER/test.py', '--cfg-path', '/tmp/tmp75vnqrhy']
[2024-08-25T05:53:28.116+0000] {standard_task_runner.py:105} INFO - Job 40: Subtask run_python_script
[2024-08-25T05:53:28.205+0000] {task_command.py:467} INFO - Running <TaskInstance: extract_data_dag.run_python_script manual__2024-08-25T05:53:27.514769+00:00 [running]> on host 05371bfc828b
[2024-08-25T05:53:28.331+0000] {taskinstance.py:3122} INFO - Exporting env vars: AIRFLOW_CTX_DAG_OWNER='***' AIRFLOW_CTX_DAG_ID='extract_data_dag' AIRFLOW_CTX_TASK_ID='run_python_script' AIRFLOW_CTX_EXECUTION_DATE='2024-08-25T05:53:27.514769+00:00' AIRFLOW_CTX_TRY_NUMBER='1' AIRFLOW_CTX_DAG_RUN_ID='manual__2024-08-25T05:53:27.514769+00:00'
[2024-08-25T05:53:28.332+0000] {taskinstance.py:731} INFO - ::endgroup::
[2024-08-25T05:53:28.350+0000] {subprocess.py:63} INFO - Tmp dir root location: /tmp
[2024-08-25T05:53:28.351+0000] {subprocess.py:75} INFO - Running command: ['/usr/bin/bash', '-c', 'python3 /spark/app/extract.py']
[2024-08-25T05:53:28.364+0000] {subprocess.py:86} INFO - Output:
[2024-08-25T05:53:29.605+0000] {subprocess.py:93} INFO - Lỗi khi đọc bảng customers: (psycopg2.OperationalError) connection to server at "127.0.1" (127.0.0.1), port 5432 failed: Connection refused
[2024-08-25T05:53:29.606+0000] {subprocess.py:93} INFO - 	Is the server running on that host and accepting TCP/IP connections?
[2024-08-25T05:53:29.607+0000] {subprocess.py:93} INFO - 
[2024-08-25T05:53:29.609+0000] {subprocess.py:93} INFO - (Background on this error at: https://sqlalche.me/e/14/e3q8)
[2024-08-25T05:53:29.610+0000] {subprocess.py:93} INFO - Lỗi khi đọc bảng accounts: (psycopg2.OperationalError) connection to server at "127.0.1" (127.0.0.1), port 5432 failed: Connection refused
[2024-08-25T05:53:29.612+0000] {subprocess.py:93} INFO - 	Is the server running on that host and accepting TCP/IP connections?
[2024-08-25T05:53:29.613+0000] {subprocess.py:93} INFO - 
[2024-08-25T05:53:29.613+0000] {subprocess.py:93} INFO - (Background on this error at: https://sqlalche.me/e/14/e3q8)
[2024-08-25T05:53:29.614+0000] {subprocess.py:93} INFO - Lỗi khi đọc bảng transactions: (psycopg2.OperationalError) connection to server at "127.0.1" (127.0.0.1), port 5432 failed: Connection refused
[2024-08-25T05:53:29.615+0000] {subprocess.py:93} INFO - 	Is the server running on that host and accepting TCP/IP connections?
[2024-08-25T05:53:29.616+0000] {subprocess.py:93} INFO - 
[2024-08-25T05:53:29.616+0000] {subprocess.py:93} INFO - (Background on this error at: https://sqlalche.me/e/14/e3q8)
[2024-08-25T05:53:29.617+0000] {subprocess.py:93} INFO - Lỗi khi đọc bảng branches: (psycopg2.OperationalError) connection to server at "127.0.1" (127.0.0.1), port 5432 failed: Connection refused
[2024-08-25T05:53:29.618+0000] {subprocess.py:93} INFO - 	Is the server running on that host and accepting TCP/IP connections?
[2024-08-25T05:53:29.619+0000] {subprocess.py:93} INFO - 
[2024-08-25T05:53:29.620+0000] {subprocess.py:93} INFO - (Background on this error at: https://sqlalche.me/e/14/e3q8)
[2024-08-25T05:53:29.620+0000] {subprocess.py:93} INFO - Lỗi khi đọc bảng loans: (psycopg2.OperationalError) connection to server at "127.0.1" (127.0.0.1), port 5432 failed: Connection refused
[2024-08-25T05:53:29.621+0000] {subprocess.py:93} INFO - 	Is the server running on that host and accepting TCP/IP connections?
[2024-08-25T05:53:29.622+0000] {subprocess.py:93} INFO - 
[2024-08-25T05:53:29.623+0000] {subprocess.py:93} INFO - (Background on this error at: https://sqlalche.me/e/14/e3q8)
[2024-08-25T05:53:29.623+0000] {subprocess.py:93} INFO - Lỗi khi đọc bảng credit_cards: (psycopg2.OperationalError) connection to server at "127.0.1" (127.0.0.1), port 5432 failed: Connection refused
[2024-08-25T05:53:29.623+0000] {subprocess.py:93} INFO - 	Is the server running on that host and accepting TCP/IP connections?
[2024-08-25T05:53:29.624+0000] {subprocess.py:93} INFO - 
[2024-08-25T05:53:29.624+0000] {subprocess.py:93} INFO - (Background on this error at: https://sqlalche.me/e/14/e3q8)
[2024-08-25T05:53:29.625+0000] {subprocess.py:93} INFO - Lỗi khi đọc bảng transaction_history: (psycopg2.OperationalError) connection to server at "127.0.1" (127.0.0.1), port 5432 failed: Connection refused
[2024-08-25T05:53:29.626+0000] {subprocess.py:93} INFO - 	Is the server running on that host and accepting TCP/IP connections?
[2024-08-25T05:53:29.627+0000] {subprocess.py:93} INFO - 
[2024-08-25T05:53:29.627+0000] {subprocess.py:93} INFO - (Background on this error at: https://sqlalche.me/e/14/e3q8)
[2024-08-25T05:53:29.628+0000] {subprocess.py:93} INFO - Lỗi khi đọc bảng payment: (psycopg2.OperationalError) connection to server at "127.0.1" (127.0.0.1), port 5432 failed: Connection refused
[2024-08-25T05:53:29.628+0000] {subprocess.py:93} INFO - 	Is the server running on that host and accepting TCP/IP connections?
[2024-08-25T05:53:29.629+0000] {subprocess.py:93} INFO - 
[2024-08-25T05:53:29.630+0000] {subprocess.py:93} INFO - (Background on this error at: https://sqlalche.me/e/14/e3q8)
[2024-08-25T05:53:29.630+0000] {subprocess.py:93} INFO - Lỗi khi đọc bảng investments: (psycopg2.OperationalError) connection to server at "127.0.1" (127.0.0.1), port 5432 failed: Connection refused
[2024-08-25T05:53:29.631+0000] {subprocess.py:93} INFO - 	Is the server running on that host and accepting TCP/IP connections?
[2024-08-25T05:53:29.631+0000] {subprocess.py:93} INFO - 
[2024-08-25T05:53:29.632+0000] {subprocess.py:93} INFO - (Background on this error at: https://sqlalche.me/e/14/e3q8)
[2024-08-25T05:53:29.781+0000] {subprocess.py:97} INFO - Command exited with return code 0
[2024-08-25T05:53:29.844+0000] {taskinstance.py:340} INFO - ::group::Post task execution logs
[2024-08-25T05:53:29.845+0000] {taskinstance.py:352} INFO - Marking task as SUCCESS. dag_id=extract_data_dag, task_id=run_python_script, run_id=manual__2024-08-25T05:53:27.514769+00:00, execution_date=20240825T055327, start_date=20240825T055328, end_date=20240825T055329
[2024-08-25T05:53:29.895+0000] {local_task_job_runner.py:261} INFO - Task exited with return code 0
[2024-08-25T05:53:29.919+0000] {taskinstance.py:3891} INFO - 0 downstream tasks scheduled from follow-on schedule check
[2024-08-25T05:53:29.922+0000] {local_task_job_runner.py:240} INFO - ::endgroup::
