[2024-08-25T05:51:24.553+0000] {local_task_job_runner.py:123} INFO - ::group::Pre task execution logs
[2024-08-25T05:51:24.578+0000] {taskinstance.py:2603} INFO - Dependencies all met for dep_context=non-requeueable deps ti=<TaskInstance: extract_data_dag.run_python_script manual__2024-08-25T05:51:23.545728+00:00 [queued]>
[2024-08-25T05:51:24.592+0000] {taskinstance.py:2603} INFO - Dependencies all met for dep_context=requeueable deps ti=<TaskInstance: extract_data_dag.run_python_script manual__2024-08-25T05:51:23.545728+00:00 [queued]>
[2024-08-25T05:51:24.592+0000] {taskinstance.py:2856} INFO - Starting attempt 1 of 2
[2024-08-25T05:51:24.611+0000] {taskinstance.py:2879} INFO - Executing <Task(BashOperator): run_python_script> on 2024-08-25 05:51:23.545728+00:00
[2024-08-25T05:51:24.621+0000] {logging_mixin.py:190} WARNING - /home/***/.local/lib/python3.12/site-packages/***/task/task_runner/standard_task_runner.py:70 DeprecationWarning: This process (pid=801) is multi-threaded, use of fork() may lead to deadlocks in the child.
[2024-08-25T05:51:24.623+0000] {standard_task_runner.py:72} INFO - Started process 802 to run task
[2024-08-25T05:51:24.621+0000] {standard_task_runner.py:104} INFO - Running: ['***', 'tasks', 'run', 'extract_data_dag', 'run_python_script', 'manual__2024-08-25T05:51:23.545728+00:00', '--job-id', '39', '--raw', '--subdir', 'DAGS_FOLDER/test.py', '--cfg-path', '/tmp/tmpy3g_9dii']
[2024-08-25T05:51:24.625+0000] {standard_task_runner.py:105} INFO - Job 39: Subtask run_python_script
[2024-08-25T05:51:24.733+0000] {task_command.py:467} INFO - Running <TaskInstance: extract_data_dag.run_python_script manual__2024-08-25T05:51:23.545728+00:00 [running]> on host 05371bfc828b
[2024-08-25T05:51:24.850+0000] {taskinstance.py:3122} INFO - Exporting env vars: AIRFLOW_CTX_DAG_OWNER='***' AIRFLOW_CTX_DAG_ID='extract_data_dag' AIRFLOW_CTX_TASK_ID='run_python_script' AIRFLOW_CTX_EXECUTION_DATE='2024-08-25T05:51:23.545728+00:00' AIRFLOW_CTX_TRY_NUMBER='1' AIRFLOW_CTX_DAG_RUN_ID='manual__2024-08-25T05:51:23.545728+00:00'
[2024-08-25T05:51:24.852+0000] {taskinstance.py:731} INFO - ::endgroup::
[2024-08-25T05:51:24.872+0000] {subprocess.py:63} INFO - Tmp dir root location: /tmp
[2024-08-25T05:51:24.873+0000] {subprocess.py:75} INFO - Running command: ['/usr/bin/bash', '-c', 'python3 /spark/app/extract.py']
[2024-08-25T05:51:24.885+0000] {subprocess.py:86} INFO - Output:
[2024-08-25T05:51:26.579+0000] {subprocess.py:93} INFO - Lỗi khi đọc bảng customers: (psycopg2.OperationalError) connection to server at "localhost" (::1), port 5432 failed: Connection refused
[2024-08-25T05:51:26.580+0000] {subprocess.py:93} INFO - 	Is the server running on that host and accepting TCP/IP connections?
[2024-08-25T05:51:26.581+0000] {subprocess.py:93} INFO - connection to server at "localhost" (127.0.0.1), port 5432 failed: Connection refused
[2024-08-25T05:51:26.581+0000] {subprocess.py:93} INFO - 	Is the server running on that host and accepting TCP/IP connections?
[2024-08-25T05:51:26.582+0000] {subprocess.py:93} INFO - 
[2024-08-25T05:51:26.582+0000] {subprocess.py:93} INFO - (Background on this error at: https://sqlalche.me/e/14/e3q8)
[2024-08-25T05:51:26.583+0000] {subprocess.py:93} INFO - Lỗi khi đọc bảng accounts: (psycopg2.OperationalError) connection to server at "localhost" (::1), port 5432 failed: Connection refused
[2024-08-25T05:51:26.584+0000] {subprocess.py:93} INFO - 	Is the server running on that host and accepting TCP/IP connections?
[2024-08-25T05:51:26.586+0000] {subprocess.py:93} INFO - connection to server at "localhost" (127.0.0.1), port 5432 failed: Connection refused
[2024-08-25T05:51:26.587+0000] {subprocess.py:93} INFO - 	Is the server running on that host and accepting TCP/IP connections?
[2024-08-25T05:51:26.587+0000] {subprocess.py:93} INFO - 
[2024-08-25T05:51:26.588+0000] {subprocess.py:93} INFO - (Background on this error at: https://sqlalche.me/e/14/e3q8)
[2024-08-25T05:51:26.588+0000] {subprocess.py:93} INFO - Lỗi khi đọc bảng transactions: (psycopg2.OperationalError) connection to server at "localhost" (::1), port 5432 failed: Connection refused
[2024-08-25T05:51:26.589+0000] {subprocess.py:93} INFO - 	Is the server running on that host and accepting TCP/IP connections?
[2024-08-25T05:51:26.589+0000] {subprocess.py:93} INFO - connection to server at "localhost" (127.0.0.1), port 5432 failed: Connection refused
[2024-08-25T05:51:26.590+0000] {subprocess.py:93} INFO - 	Is the server running on that host and accepting TCP/IP connections?
[2024-08-25T05:51:26.591+0000] {subprocess.py:93} INFO - 
[2024-08-25T05:51:26.591+0000] {subprocess.py:93} INFO - (Background on this error at: https://sqlalche.me/e/14/e3q8)
[2024-08-25T05:51:26.591+0000] {subprocess.py:93} INFO - Lỗi khi đọc bảng branches: (psycopg2.OperationalError) connection to server at "localhost" (::1), port 5432 failed: Connection refused
[2024-08-25T05:51:26.592+0000] {subprocess.py:93} INFO - 	Is the server running on that host and accepting TCP/IP connections?
[2024-08-25T05:51:26.593+0000] {subprocess.py:93} INFO - connection to server at "localhost" (127.0.0.1), port 5432 failed: Connection refused
[2024-08-25T05:51:26.594+0000] {subprocess.py:93} INFO - 	Is the server running on that host and accepting TCP/IP connections?
[2024-08-25T05:51:26.594+0000] {subprocess.py:93} INFO - 
[2024-08-25T05:51:26.595+0000] {subprocess.py:93} INFO - (Background on this error at: https://sqlalche.me/e/14/e3q8)
[2024-08-25T05:51:26.595+0000] {subprocess.py:93} INFO - Lỗi khi đọc bảng loans: (psycopg2.OperationalError) connection to server at "localhost" (::1), port 5432 failed: Connection refused
[2024-08-25T05:51:26.596+0000] {subprocess.py:93} INFO - 	Is the server running on that host and accepting TCP/IP connections?
[2024-08-25T05:51:26.596+0000] {subprocess.py:93} INFO - connection to server at "localhost" (127.0.0.1), port 5432 failed: Connection refused
[2024-08-25T05:51:26.597+0000] {subprocess.py:93} INFO - 	Is the server running on that host and accepting TCP/IP connections?
[2024-08-25T05:51:26.597+0000] {subprocess.py:93} INFO - 
[2024-08-25T05:51:26.598+0000] {subprocess.py:93} INFO - (Background on this error at: https://sqlalche.me/e/14/e3q8)
[2024-08-25T05:51:26.598+0000] {subprocess.py:93} INFO - Lỗi khi đọc bảng credit_cards: (psycopg2.OperationalError) connection to server at "localhost" (::1), port 5432 failed: Connection refused
[2024-08-25T05:51:26.599+0000] {subprocess.py:93} INFO - 	Is the server running on that host and accepting TCP/IP connections?
[2024-08-25T05:51:26.600+0000] {subprocess.py:93} INFO - connection to server at "localhost" (127.0.0.1), port 5432 failed: Connection refused
[2024-08-25T05:51:26.601+0000] {subprocess.py:93} INFO - 	Is the server running on that host and accepting TCP/IP connections?
[2024-08-25T05:51:26.602+0000] {subprocess.py:93} INFO - 
[2024-08-25T05:51:26.603+0000] {subprocess.py:93} INFO - (Background on this error at: https://sqlalche.me/e/14/e3q8)
[2024-08-25T05:51:26.603+0000] {subprocess.py:93} INFO - Lỗi khi đọc bảng transaction_history: (psycopg2.OperationalError) connection to server at "localhost" (::1), port 5432 failed: Connection refused
[2024-08-25T05:51:26.604+0000] {subprocess.py:93} INFO - 	Is the server running on that host and accepting TCP/IP connections?
[2024-08-25T05:51:26.605+0000] {subprocess.py:93} INFO - connection to server at "localhost" (127.0.0.1), port 5432 failed: Connection refused
[2024-08-25T05:51:26.607+0000] {subprocess.py:93} INFO - 	Is the server running on that host and accepting TCP/IP connections?
[2024-08-25T05:51:26.608+0000] {subprocess.py:93} INFO - 
[2024-08-25T05:51:26.609+0000] {subprocess.py:93} INFO - (Background on this error at: https://sqlalche.me/e/14/e3q8)
[2024-08-25T05:51:26.609+0000] {subprocess.py:93} INFO - Lỗi khi đọc bảng payment: (psycopg2.OperationalError) connection to server at "localhost" (::1), port 5432 failed: Connection refused
[2024-08-25T05:51:26.610+0000] {subprocess.py:93} INFO - 	Is the server running on that host and accepting TCP/IP connections?
[2024-08-25T05:51:26.611+0000] {subprocess.py:93} INFO - connection to server at "localhost" (127.0.0.1), port 5432 failed: Connection refused
[2024-08-25T05:51:26.611+0000] {subprocess.py:93} INFO - 	Is the server running on that host and accepting TCP/IP connections?
[2024-08-25T05:51:26.612+0000] {subprocess.py:93} INFO - 
[2024-08-25T05:51:26.613+0000] {subprocess.py:93} INFO - (Background on this error at: https://sqlalche.me/e/14/e3q8)
[2024-08-25T05:51:26.614+0000] {subprocess.py:93} INFO - Lỗi khi đọc bảng investments: (psycopg2.OperationalError) connection to server at "localhost" (::1), port 5432 failed: Connection refused
[2024-08-25T05:51:26.614+0000] {subprocess.py:93} INFO - 	Is the server running on that host and accepting TCP/IP connections?
[2024-08-25T05:51:26.615+0000] {subprocess.py:93} INFO - connection to server at "localhost" (127.0.0.1), port 5432 failed: Connection refused
[2024-08-25T05:51:26.615+0000] {subprocess.py:93} INFO - 	Is the server running on that host and accepting TCP/IP connections?
[2024-08-25T05:51:26.616+0000] {subprocess.py:93} INFO - 
[2024-08-25T05:51:26.616+0000] {subprocess.py:93} INFO - (Background on this error at: https://sqlalche.me/e/14/e3q8)
[2024-08-25T05:51:26.799+0000] {subprocess.py:97} INFO - Command exited with return code 0
[2024-08-25T05:51:26.843+0000] {taskinstance.py:340} INFO - ::group::Post task execution logs
[2024-08-25T05:51:26.844+0000] {taskinstance.py:352} INFO - Marking task as SUCCESS. dag_id=extract_data_dag, task_id=run_python_script, run_id=manual__2024-08-25T05:51:23.545728+00:00, execution_date=20240825T055123, start_date=20240825T055124, end_date=20240825T055126
[2024-08-25T05:51:26.897+0000] {local_task_job_runner.py:261} INFO - Task exited with return code 0
[2024-08-25T05:51:26.928+0000] {taskinstance.py:3891} INFO - 0 downstream tasks scheduled from follow-on schedule check
[2024-08-25T05:51:26.930+0000] {local_task_job_runner.py:240} INFO - ::endgroup::
