[2024-08-25T05:54:57.669+0000] {local_task_job_runner.py:123} INFO - ::group::Pre task execution logs
[2024-08-25T05:54:57.698+0000] {taskinstance.py:2603} INFO - Dependencies all met for dep_context=non-requeueable deps ti=<TaskInstance: extract_data_dag.run_python_script manual__2024-08-25T05:49:55.756441+00:00 [queued]>
[2024-08-25T05:54:57.713+0000] {taskinstance.py:2603} INFO - Dependencies all met for dep_context=requeueable deps ti=<TaskInstance: extract_data_dag.run_python_script manual__2024-08-25T05:49:55.756441+00:00 [queued]>
[2024-08-25T05:54:57.714+0000] {taskinstance.py:2856} INFO - Starting attempt 2 of 2
[2024-08-25T05:54:57.734+0000] {taskinstance.py:2879} INFO - Executing <Task(BashOperator): run_python_script> on 2024-08-25 05:49:55.756441+00:00
[2024-08-25T05:54:57.745+0000] {logging_mixin.py:190} WARNING - /home/***/.local/lib/python3.12/site-packages/***/task/task_runner/standard_task_runner.py:70 DeprecationWarning: This process (pid=856) is multi-threaded, use of fork() may lead to deadlocks in the child.
[2024-08-25T05:54:57.747+0000] {standard_task_runner.py:72} INFO - Started process 857 to run task
[2024-08-25T05:54:57.744+0000] {standard_task_runner.py:104} INFO - Running: ['***', 'tasks', 'run', 'extract_data_dag', 'run_python_script', 'manual__2024-08-25T05:49:55.756441+00:00', '--job-id', '41', '--raw', '--subdir', 'DAGS_FOLDER/test.py', '--cfg-path', '/tmp/tmpqda0nwjq']
[2024-08-25T05:54:57.748+0000] {standard_task_runner.py:105} INFO - Job 41: Subtask run_python_script
[2024-08-25T05:54:57.819+0000] {task_command.py:467} INFO - Running <TaskInstance: extract_data_dag.run_python_script manual__2024-08-25T05:49:55.756441+00:00 [running]> on host 05371bfc828b
[2024-08-25T05:54:57.936+0000] {taskinstance.py:3122} INFO - Exporting env vars: AIRFLOW_CTX_DAG_OWNER='***' AIRFLOW_CTX_DAG_ID='extract_data_dag' AIRFLOW_CTX_TASK_ID='run_python_script' AIRFLOW_CTX_EXECUTION_DATE='2024-08-25T05:49:55.756441+00:00' AIRFLOW_CTX_TRY_NUMBER='2' AIRFLOW_CTX_DAG_RUN_ID='manual__2024-08-25T05:49:55.756441+00:00'
[2024-08-25T05:54:57.938+0000] {taskinstance.py:731} INFO - ::endgroup::
[2024-08-25T05:54:57.961+0000] {subprocess.py:63} INFO - Tmp dir root location: /tmp
[2024-08-25T05:54:57.964+0000] {subprocess.py:75} INFO - Running command: ['/usr/bin/bash', '-c', 'python3 /spark/app/extract.py']
[2024-08-25T05:54:57.979+0000] {subprocess.py:86} INFO - Output:
[2024-08-25T05:54:59.457+0000] {subprocess.py:93} INFO - Lỗi khi đọc bảng customers: (psycopg2.OperationalError) connection to server at "127.0.1" (127.0.0.1), port 5432 failed: Connection refused
[2024-08-25T05:54:59.458+0000] {subprocess.py:93} INFO - 	Is the server running on that host and accepting TCP/IP connections?
[2024-08-25T05:54:59.458+0000] {subprocess.py:93} INFO - 
[2024-08-25T05:54:59.459+0000] {subprocess.py:93} INFO - (Background on this error at: https://sqlalche.me/e/14/e3q8)
[2024-08-25T05:54:59.460+0000] {subprocess.py:93} INFO - Lỗi khi đọc bảng accounts: (psycopg2.OperationalError) connection to server at "127.0.1" (127.0.0.1), port 5432 failed: Connection refused
[2024-08-25T05:54:59.461+0000] {subprocess.py:93} INFO - 	Is the server running on that host and accepting TCP/IP connections?
[2024-08-25T05:54:59.462+0000] {subprocess.py:93} INFO - 
[2024-08-25T05:54:59.464+0000] {subprocess.py:93} INFO - (Background on this error at: https://sqlalche.me/e/14/e3q8)
[2024-08-25T05:54:59.465+0000] {subprocess.py:93} INFO - Lỗi khi đọc bảng transactions: (psycopg2.OperationalError) connection to server at "127.0.1" (127.0.0.1), port 5432 failed: Connection refused
[2024-08-25T05:54:59.466+0000] {subprocess.py:93} INFO - 	Is the server running on that host and accepting TCP/IP connections?
[2024-08-25T05:54:59.467+0000] {subprocess.py:93} INFO - 
[2024-08-25T05:54:59.468+0000] {subprocess.py:93} INFO - (Background on this error at: https://sqlalche.me/e/14/e3q8)
[2024-08-25T05:54:59.469+0000] {subprocess.py:93} INFO - Lỗi khi đọc bảng branches: (psycopg2.OperationalError) connection to server at "127.0.1" (127.0.0.1), port 5432 failed: Connection refused
[2024-08-25T05:54:59.470+0000] {subprocess.py:93} INFO - 	Is the server running on that host and accepting TCP/IP connections?
[2024-08-25T05:54:59.472+0000] {subprocess.py:93} INFO - 
[2024-08-25T05:54:59.473+0000] {subprocess.py:93} INFO - (Background on this error at: https://sqlalche.me/e/14/e3q8)
[2024-08-25T05:54:59.473+0000] {subprocess.py:93} INFO - Lỗi khi đọc bảng loans: (psycopg2.OperationalError) connection to server at "127.0.1" (127.0.0.1), port 5432 failed: Connection refused
[2024-08-25T05:54:59.474+0000] {subprocess.py:93} INFO - 	Is the server running on that host and accepting TCP/IP connections?
[2024-08-25T05:54:59.474+0000] {subprocess.py:93} INFO - 
[2024-08-25T05:54:59.476+0000] {subprocess.py:93} INFO - (Background on this error at: https://sqlalche.me/e/14/e3q8)
[2024-08-25T05:54:59.478+0000] {subprocess.py:93} INFO - Lỗi khi đọc bảng credit_cards: (psycopg2.OperationalError) connection to server at "127.0.1" (127.0.0.1), port 5432 failed: Connection refused
[2024-08-25T05:54:59.478+0000] {subprocess.py:93} INFO - 	Is the server running on that host and accepting TCP/IP connections?
[2024-08-25T05:54:59.479+0000] {subprocess.py:93} INFO - 
[2024-08-25T05:54:59.480+0000] {subprocess.py:93} INFO - (Background on this error at: https://sqlalche.me/e/14/e3q8)
[2024-08-25T05:54:59.481+0000] {subprocess.py:93} INFO - Lỗi khi đọc bảng transaction_history: (psycopg2.OperationalError) connection to server at "127.0.1" (127.0.0.1), port 5432 failed: Connection refused
[2024-08-25T05:54:59.482+0000] {subprocess.py:93} INFO - 	Is the server running on that host and accepting TCP/IP connections?
[2024-08-25T05:54:59.483+0000] {subprocess.py:93} INFO - 
[2024-08-25T05:54:59.483+0000] {subprocess.py:93} INFO - (Background on this error at: https://sqlalche.me/e/14/e3q8)
[2024-08-25T05:54:59.484+0000] {subprocess.py:93} INFO - Lỗi khi đọc bảng payment: (psycopg2.OperationalError) connection to server at "127.0.1" (127.0.0.1), port 5432 failed: Connection refused
[2024-08-25T05:54:59.485+0000] {subprocess.py:93} INFO - 	Is the server running on that host and accepting TCP/IP connections?
[2024-08-25T05:54:59.486+0000] {subprocess.py:93} INFO - 
[2024-08-25T05:54:59.487+0000] {subprocess.py:93} INFO - (Background on this error at: https://sqlalche.me/e/14/e3q8)
[2024-08-25T05:54:59.488+0000] {subprocess.py:93} INFO - Lỗi khi đọc bảng investments: (psycopg2.OperationalError) connection to server at "127.0.1" (127.0.0.1), port 5432 failed: Connection refused
[2024-08-25T05:54:59.488+0000] {subprocess.py:93} INFO - 	Is the server running on that host and accepting TCP/IP connections?
[2024-08-25T05:54:59.490+0000] {subprocess.py:93} INFO - 
[2024-08-25T05:54:59.491+0000] {subprocess.py:93} INFO - (Background on this error at: https://sqlalche.me/e/14/e3q8)
[2024-08-25T05:54:59.631+0000] {subprocess.py:97} INFO - Command exited with return code 0
[2024-08-25T05:54:59.696+0000] {taskinstance.py:340} INFO - ::group::Post task execution logs
[2024-08-25T05:54:59.697+0000] {taskinstance.py:352} INFO - Marking task as SUCCESS. dag_id=extract_data_dag, task_id=run_python_script, run_id=manual__2024-08-25T05:49:55.756441+00:00, execution_date=20240825T054955, start_date=20240825T055457, end_date=20240825T055459
[2024-08-25T05:54:59.733+0000] {local_task_job_runner.py:261} INFO - Task exited with return code 0
[2024-08-25T05:54:59.761+0000] {taskinstance.py:3891} INFO - 0 downstream tasks scheduled from follow-on schedule check
[2024-08-25T05:54:59.767+0000] {local_task_job_runner.py:240} INFO - ::endgroup::
